<?xml version="1.0" ?>
<robot name="bogie" xmlns:xacro="http://www.ros.org/wiki/xacro">

<xacro:include filename="$(find bogie_description)/urdf/materials.xacro" />
<xacro:include filename="$(find bogie_description)/urdf/bogie.trans" />
<xacro:include filename="$(find bogie_description)/urdf/bogie.gazebo" />
<link name="base_footprint"/>

<link name="base_link">
  <inertial>
    <origin xyz="-0.09506667654178791 -8.169035858724671e-11 0.18164371614615132" rpy="0 0 0"/>
    <mass value="2.101736662966977"/>
    <inertia ixx="0.0448" iyy="0.045392" izz="0.039355" ixy="-1e-06" iyz="-0.0" ixz="4.9e-05"/>
  </inertial>
  <visual>
    <origin xyz="0 0 0" rpy="0 0 0"/>
    <geometry>
      <mesh filename="package://bogie_description/meshes/base_link.stl" scale="0.001 0.001 0.001"/>
    </geometry>
    <material name="silver"/>
  </visual>
  <collision>
    <origin xyz="0 0 0" rpy="0 0 0"/>
    <geometry>
      <mesh filename="package://bogie_description/meshes/base_link.stl" scale="0.001 0.001 0.001"/>
    </geometry>
  </collision>
</link>

<link name="right_wheel">
  <inertial>
    <origin xyz="4.006936401468532e-17 -0.010000000000000023 6.332993920943331e-10" rpy="0 0 0"/>
    <mass value="0.10554573218816608"/>
    <inertia ixx="5.1e-05" iyy="9.5e-05" izz="5.1e-05" ixy="-0.0" iyz="0.0" ixz="0.0"/>
  </inertial>
  <visual>
    <origin xyz="-0.0 0.115 -0.0425" rpy="0 0 0"/>
    <geometry>
      <mesh filename="package://bogie_description/meshes/right_wheel.stl" scale="0.001 0.001 0.001"/>
    </geometry>
    <material name="silver"/>
  </visual>
  <collision>
    <origin xyz="-0.0 0.115 -0.0425" rpy="0 0 0"/>
    <geometry>
      <mesh filename="package://bogie_description/meshes/right_wheel.stl" scale="0.001 0.001 0.001"/>
    </geometry>
  </collision>
</link>

<link name="left_wheel">
  <inertial>
    <origin xyz="4.006936401468532e-17 0.009999999999999995 6.332993920943331e-10" rpy="0 0 0"/>
    <mass value="0.10554573218816608"/>
    <inertia ixx="5.1e-05" iyy="9.5e-05" izz="5.1e-05" ixy="-0.0" iyz="0.0" ixz="0.0"/>
  </inertial>
  <visual>
    <origin xyz="-0.0 -0.115 -0.0425" rpy="0 0 0"/>
    <geometry>
      <mesh filename="package://bogie_description/meshes/left_wheel.stl" scale="0.001 0.001 0.001"/>
    </geometry>
    <material name="silver"/>
  </visual>
  <collision>
    <origin xyz="-0.0 -0.115 -0.0425" rpy="0 0 0"/>
    <geometry>
      <mesh filename="package://bogie_description/meshes/left_wheel.stl" scale="0.001 0.001 0.001"/>
    </geometry>
  </collision>
</link>

<link name="base_laser_link">
  <inertial>
    <origin xyz="-1.4156103095297468e-09 2.2723795526381552e-17 0.009749999999999981" rpy="0 0 0"/>
    <mass value="0.12202283587753035"/>
    <inertia ixx="4.1e-05" iyy="4.1e-05" izz="7.5e-05" ixy="-0.0" iyz="-0.0" ixz="0.0"/>
  </inertial>
  <visual>
    <origin xyz="0.095 -0.0 -0.334" rpy="0 0 0"/>
    <geometry>
      <mesh filename="package://bogie_description/meshes/base_laser_link.stl" scale="0.001 0.001 0.001"/>
    </geometry>
    <material name="silver"/>
  </visual>
  <collision>
    <origin xyz="0.095 -0.0 -0.334" rpy="0 0 0"/>
    <geometry>
      <mesh filename="package://bogie_description/meshes/base_laser_link.stl" scale="0.001 0.001 0.001"/>
    </geometry>
  </collision>
</link>

<link name="imu_link">
  <inertial>
    <origin xyz="0.0 0.0 -0.0050000000000000044" rpy="0 0 0"/>
    <mass value="0.0037199999999999998"/>
    <inertia ixx="0.0" iyy="0.0" izz="0.0" ixy="0.0" iyz="0.0" ixz="0.0"/>
  </inertial>
  <visual>
    <origin xyz="0.095 -0.0 -0.2875" rpy="0 0 0"/>
    <geometry>
      <mesh filename="package://bogie_description/meshes/imu_link.stl" scale="0.001 0.001 0.001"/>
    </geometry>
    <material name="silver"/>
  </visual>
  <collision>
    <origin xyz="0.095 -0.0 -0.2875" rpy="0 0 0"/>
    <geometry>
      <mesh filename="package://bogie_description/meshes/imu_link.stl" scale="0.001 0.001 0.001"/>
    </geometry>
  </collision>
</link>

<joint name="base_link_joint" type="fixed">
  <origin xyz="-0.0 0.0 0.0" rpy="0 0 0"/>
  <parent link="base_footprint"/>
  <child link="base_link"/>
</joint>

<joint name="Revolute 1" type="continuous">
  <origin xyz="0.0 -0.115 0.0425" rpy="0 0 0"/>
  <parent link="base_link"/>
  <child link="right_wheel"/>
  <axis xyz="0.0 -1.0 0.0"/>
</joint>

<joint name="Revolute 2" type="continuous">
  <origin xyz="0.0 0.115 0.0425" rpy="0 0 0"/>
  <parent link="base_link"/>
  <child link="left_wheel"/>
  <axis xyz="0.0 1.0 0.0"/>
</joint>

<joint name="Rigid 3" type="fixed">
  <origin xyz="-0.095 0.0 0.334" rpy="0 0 0"/>
  <parent link="base_link"/>
  <child link="base_laser_link"/>
</joint>

<joint name="Rigid 4" type="fixed">
  <origin xyz="-0.095 0.0 0.2875" rpy="0 0 0"/>
  <parent link="base_link"/>
  <child link="imu_link"/>
</joint>

</robot>
